<?xml version="1.0"?>
<!--  ==========================================================================================  -->
<!--  |    This document was autogenerated by scene_to_spawner from g500ARM5BPeg.xacro         |  -->
<!--  |    EDITING THIS FILE BY HAND IS NOT RECOMMENDED                                        |  -->
<!--  ==========================================================================================  -->
<robot xmlns:xacro="http://www.ros.org/wiki/xacro" name="g500_B">
  <link name="base_link">
    <visual>
      <origin rpy="-1.57079632679 0 3.14159265359" xyz="-0.2 0 0.75"/>
      <geometry>
        <mesh filename="robot/GIRONA500/g500_March11.osg"/>
      </geometry>
    </visual>
    <!--collision>
      <origin xyz="0 0 0" rpy="0 0 0"/>
      <geometry>
	<box size="1 1 1"/>
      </geometry>
    </collision-->
    </link>
  <link name="part0">
    <visual>
      <origin rpy="3.14159265359 0 0" xyz="0 0 0"/>
      <geometry>
        <mesh filename="robot/ARM5E/ARM5E_part0.osg"/>
      </geometry>
    </visual>
    </link>
  <joint name="baselink_to_part0" type="fixed">
    <parent link="base_link"/>
    <child link="part0"/>
    <origin rpy="0 0 3.14159265359" xyz="0 0 0.95"/>
  </joint>
  <link name="part1">
    <visual>
      <origin rpy="3.14159265359 0 0" xyz="0.0 0 -0.13"/>
      <geometry>
        <mesh filename="robot/ARM5E/ARM5E_part1.osg"/>
      </geometry>
    </visual>
    </link>
  <joint name="Slew" type="revolute">
    <parent link="part0"/>
    <child link="part1"/>
    <axis xyz="0 0 1"/>
    <origin rpy="0 0 0" xyz="0 0 0.13"/>
    <dynamics damping="0.8"/>
    <limit effort="500" lower="-1.57079632679" upper="0.5488" velocity="1"/>
  </joint>
  <link name="part2">
    <visual>
      <origin rpy="1.57079632679 0 -0.087262726" xyz="0 0 0"/>
      <geometry>
        <mesh filename="robot/ARM5E/ARM5E_part2.osg"/>
      </geometry>
    </visual>
    </link>
  <joint name="Shoulder" type="revolute">
    <parent link="part1"/>
    <child link="part2"/>
    <axis xyz="0 0 1"/>
    <origin rpy="1.57079632679 0 0" xyz="0.08052 0 0"/>
    <dynamics damping="0.8"/>
    <limit effort="500.0" lower="0" upper="1.58665" velocity="1.0"/>
  </joint>
  <link name="part3">
    <visual>
      <origin rpy="1.57079632679 0 0.4014" xyz="0 0 0"/>
      <geometry>
        <mesh filename="robot/ARM5E/ARM5E_part3.osg"/>
      </geometry>
    </visual>
    </link>
  <joint name="Elbow" type="revolute">
    <parent link="part2"/>
    <child link="part3"/>
    <axis xyz="0 0 1"/>
    <origin rpy="0 0 0.139277274" xyz="0.438492379277 0.0614700067987 0"/>
    <dynamics damping="0.8"/>
    <limit effort="500.0" lower="0" upper="2.15294" velocity="1.0"/>
  </joint>
  <link name="part4_base">
    <visual>
      <origin rpy="0 -1.57079632679 0" xyz="0 0 -0.028"/>
      <geometry>
        <mesh filename="robot/ARM5E/ARM5E_part4_base.osg"/>
      </geometry>
    </visual>
    </link>
  <joint name="JawRotate" type="revolute">
    <parent link="part3"/>
    <child link="part4_base"/>
    <axis xyz="0 0 1"/>
    <origin rpy="1.57079632679 0 1.972222055" xyz="0.349117258152 0.058023572508 0"/>
    <dynamics damping="0.8"/>
    <limit effort="200" lower="-3.14159265359" upper="3.14159265359" velocity="1"/>
  </joint>
  <link name="end_effector">
    <!-- From the kinematic base of the robot -->
  </link>
  <joint name="part4_base_to_end_effector" type="fixed">
    <parent link="part4_base"/>
    <child link="end_effector"/>
    <origin rpy="0 0 0" xyz="0 0 0.1485"/>
  </joint>
  <link name="peg"> 
  </link>
  <joint name="ee_to_peg" type="fixed">
    <parent link="end_effector"/>
    <child link="peg"/>
    <origin rpy="0 0 -1.5707991565684896" xyz="-0.000005641198616 -1.9999781062135944 0.006895626409301414"/>
  </joint>
  <link name="part4_jaw1">
    <visual>
      <origin rpy="0 -1.57079632679 0" xyz="0 0 0"/>
      <geometry>
        <mesh filename="robot/ARM5E/ARM5E_part4_jaw1.osg"/>
      </geometry>
    </visual>
    </link>
  <joint name="JawOpening" type="revolute">
    <parent link="part4_base"/>
    <child link="part4_jaw1"/>
    <axis xyz="0 -1 0"/>
    <origin rpy="0 0 0" xyz="-0.04 0 0.045"/>
    <dynamics damping="0.8"/>
    <limit effort="100.0" lower="-0.05816" upper="1.337696" velocity="1.0"/>
  </joint>
  <link name="part4_jaw2">
    <visual>
      <origin rpy="0 -1.57079632679 0" xyz="0 0 0"/>
      <geometry>
        <mesh filename="robot/ARM5E/ARM5E_part4_jaw2.osg"/>
      </geometry>
    </visual>
    </link>
  <joint name="JawOpening2" type="revolute">
    <parent link="part4_base"/>
    <child link="part4_jaw2"/>
    <axis xyz="0 1 0"/>
    <origin rpy="0 0 0" xyz="0.04 0 0.0450"/>
    <dynamics damping="0.8"/>
    <limit effort="100" lower="-0.05816" upper="1.337696" velocity="1.0"/>
  </joint>
</robot>
